Workbook
Name LOCAL_DATE_SEPARATOR: #REF!
Name _Toc301930478: TestDesign!$B$378
Name ACTION: #REF!
Name _Toc301930468: TestDesign!$B$218
Name LOCAL_DAY_FORMAT: #REF!
Name LOCAL_SECOND_FORMAT: #REF!
Name LOCAL_MONTH_FORMAT: #REF!
Name LOCAL_TIME_SEPARATOR: #REF!
Name LOCAL_MINUTE_FORMAT: #REF!
Name LOCAL_YEAR_FORMAT: #REF!
Name LOCAL_HOUR_FORMAT: #REF!

Sheet Cover
B2: TEST CASE
B4: Project Name | C4: Traveloka - Tìm kiếm chuyến bay | F4: Creator | G4: Phan Thị Huỳnh Như
B5: Project Code | C5: TVL_FL_SEARCH | F5: Reviewer/Approver | G5: Trần Thị B
B6: Document Code | C6: =C5&"_TestCase_V0.1" -> TVL_FL_SEARCH_TestCase_V0.1 | F6: Issue Date | G6: 46312
F7: Version | G7: 0.1
B10: Record of change
B11: Effective Date | C11: Version | D11: Change Item | E11: *A,D,M | F11: Change description | G11: Reference
B12: 46312 | C12: 0.1 | E12: A | F12: Tạo 25 Test Case cho chức năng tìm kiếm chuyến bay | G12: TestDesign

Sheet Test case List
D1: TEST CASE LIST
B3: Project Name | D3: =Cover!C4 -> Traveloka - Tìm kiếm chuyến bay
B4: Project Code | D4: =Cover!C5 -> TVL_FL_SEARCH
B5: Test Environment Setup Description | D5: 1. Automation Testing Tool: Katalon Studio 2. Programming Language: Groovy / Java 3. Web Browsers: Google Chrome, Microsoft Edge 4. Application Under Test: Traveloka Flight Module 5. OS: Windows 11 / macOS
B8: No | C8: Function Name | D8: Sheet Name | E8: Description | F8: Pre-Condition
B9: 1 | C9: Tìm kiếm chuyến bay | D9: Tìm kiếm chuyến bay | E9: Kiểm tra form tìm kiếm, chọn điểm đi/đến, ngày bay, hành khách, hạng ghế và thực thi tìm kiếm | F9: Đã truy cập Trang chủ Traveloka và mở giao diện Đặt vé máy bay
B10: 2 | C10: Xem danh sách & Chọn chuyến bay | D10: Xem danh sách và chọn chuyến bay | E10: Kiểm tra hiển thị danh sách, bộ lọc, sắp xếp, xem chi tiết và chọn hạng vé | F10: Đã hoàn thành tìm kiếm chuyến bay hợp lệ
B11: 3 | C11: Đặt chỗ & Thanh toán | D11: Đặt chỗ và thanh toán | E11: Kiểm tra điền thông tin hành khách, dịch vụ bổ sung, mã giảm giá và chọn phương thức thanh toán | F11: Đã chọn thành công chuyến bay mong muốn

Sheet TestDesign
A1: Requirement Level 1 | B1: Requirement Level 2 | C1: Requirement Level 3 | D1: Test Criteria | E1: Test Type | F1: Note
A2: 1.1 Tìm kiếm chuyến bay | B2: 1.1.1 Điều hướng & Giao diện | C2: Hiển thị menu Vé máy bay | D2: Kiểm tra hiển thị icon/menu "Vé máy bay" trên Trang chủ Traveloka | E2: GUI | F2: Đúng vị trí header chính
C3: Truy cập trang tìm kiếm | D3: Kiểm tra click chọn "Vé máy bay" chuyển hướng sang giao diện Tìm kiếm | E3: Function | F3: Tải đầy đủ form tìm kiếm
C4: Bố cục Form tìm kiếm | D4: Kiểm tra bố cục giao diện chính của form Đặt vé máy bay | E4: GUI | F4: Hiển thị đủ các trường dữ liệu
B5: 1.1.2 Loại chuyến bay | C5: Mặc định loại chuyến bay | D5: Kiểm tra mặc định chọn loại vé "Một chiều" khi mới truy cập trang | E5: Function | F5: Trường Ngày về bị disabled
C6: Chuyển sang Khứ hồi | D6: Kiểm tra chuyển đổi từ loại vé "Một chiều" sang "Khứ hồi" | E6: Function | F6: Kích hoạt trường chọn Ngày về
C7: Chuyển về Một chiều | D7: Kiểm tra chuyển đổi từ loại vé "Khứ hồi" về "Một chiều" | E7: Function | F7: Ẩn/disabled Ngày về và xóa dữ liệu đã chọn
B8: 1.1.3 Chọn Điểm đi & Điểm đến | C8: Gợi ý có dấu | D8: Kiểm tra hiển thị danh sách gợi ý khi nhập từ khóa thành phố/sân bay tiếng Việt có dấu | E8: Function | F8: Hiển thị gợi ý sân bay phù hợp
C9: Gợi ý không dấu | D9: Kiểm tra hiển thị danh sách gợi ý khi nhập từ khóa không dấu | E9: Function | F9: Tìm kiếm linh hoạt theo từ khóa
C10: Gợi ý mã IATA | D10: Kiểm tra gợi ý chuẩn xác khi nhập mã IATA của sân bay | E10: Function | F10: Mã sân bay 3 ký tự (VD: DAD, SGN, HAN)
C11: Nhập địa điểm không tồn tại | D11: Kiểm tra nhập từ khóa địa điểm không tồn tại | E11: Validation | F11: Hiển thị thông báo không tìm thấy kết quả
C12: Nút xóa nhanh [X] | D12: Kiểm tra nút xóa nhanh (icon [X]) tại ô Điểm đi / Điểm đến | E12: GUI | F12: Khôi phục về trạng thái placeholder
C13: Nút hoán đổi [⇆] | D13: Kiểm tra chức năng hoán đổi [⇆] vị trí giữa Điểm đi và Điểm đến | E13: Function | F13: Tráo đổi vị trí dữ liệu 2 ô
C14: Điểm trùng nhau | D14: Kiểm tra không cho phép tìm kiếm khi Điểm đi trùng với Điểm đến | E14: Validation | F14: Báo lỗi trùng điểm đi và điểm đến
B15: 1.1.4 Chọn Ngày bay | C15: Chọn Ngày đi hợp lệ | D15: Kiểm tra chọn Ngày đi hợp lệ trong tương lai | E15: Function | F15: Hiển thị đúng định dạng ngày
C16: Chặn ngày quá khứ | D16: Kiểm tra không cho phép chọn Ngày đi hoặc Ngày về trong quá khứ | E16: Validation | F16: Các ngày quá khứ bị mờ/disabled
C17: Tự động gợi ý Ngày về | D17: Kiểm tra tự động thiết lập Ngày về mặc định khi chọn vé Khứ hồi | E17: Function | F17: Gợi ý Ngày về >= Ngày đi
C18: Ngày về trước Ngày đi | D18: Kiểm tra vé khứ hồi báo lỗi khi chọn Ngày về trước Ngày đi | E18: Validation | F18: Ràng buộc logic thời gian bay
C19: Bay và về cùng ngày | D19: Kiểm tra chọn Ngày đi và Ngày về trùng nhau đối meo đối với vé Khứ hồi | E19: Function | F19: Cho phép bay và về trong ngày
B20: 1.1.5 Chọn Số hành khách & Hạng ghế | C20: Tăng/giảm Người lớn | D20: Kiểm tra thay đổi số lượng hành khách Người lớn bằng nút [+] và [-] | E20: Function | F20: Số người lớn tối thiểu là 1
C21: Ràng buộc Em bé | D21: Kiểm tra không cho phép số lượng Em bé nhiều hơn số lượng Người lớn | E21: Validation | F21: Quy định an toàn hàng không (tối đa 1 em bé/người lớn)
C22: Giới hạn tổng khách | D22: Kiểm tra giới hạn tổng số lượng hành khách tối đa 9 người/lần đặt | E22: Boundary | F22: Giới hạn tối đa 9 khách/đơn đặt
C23: Chọn Hạng ghế | D23: Kiểm tra chọn các Hạng ghế (Phổ thông, Phổ thông đặc biệt, Thương gia, Hạng nhất) | E23: Function | F23: Cập nhật đúng tên hạng ghế đã chọn
B24: 1.1.6 Thực thi Tìm kiếm | C24: Tìm kiếm Một chiều | D24: Kiểm tra tìm kiếm thành công với dữ liệu một chiều hợp lệ | E24: Function | F24: Chuyển sang trang danh sách chuyến bay
C25: Tìm kiếm Khứ hồi | D25: Kiểm tra tìm kiếm thành công với dữ liệu khứ hồi hợp lệ | E25: Function | F25: Chuyển sang trang danh sách đi và về
C26: Bỏ trống thông tin | D26: Kiểm tra báo lỗi khi để trống trường bắt buộc (Điểm đi / Điểm đến / Ngày đi) | E26: Validation | F26: Hiển thị cảnh báo đỏ tại trường trống
A27: 1.2 Xem danh sách & Chọn chuyến bay | B27: 1.2.1 Hiển thị thông tin tổng quan | C27: Hiển thị thẻ chuyến bay | D27: Kiểm tra hiển thị đầy đủ thông tin trên thẻ chuyến bay kết quả | E27: GUI | F27: Hiển thị đủ logo, thời gian, loại chuyến và giá
C28: Số lượng chuyến bay | D28: Kiểm tra hiển thị số lượng tổng các chuyến bay tìm thấy | E28: GUI | F28: Hiển thị đúng tổng số chuyến bay tìm thấy
C29: Thanh chọn ngày nhanh | D29: Kiểm tra chuyển đổi ngày bay từ Thanh chọn ngày nhanh (Date Strip) | E29: Function | F29: Tải lại danh sách chuyến bay của ngày mới
B30: 1.2.2 Lọc theo Số điểm dừng & Hãng bay | C30: Lọc Bay thẳng | D30: Kiểm tra lọc danh sách chỉ hiển thị chuyến "Bay thẳng" | E30: Function | F30: Chỉ hiển thị chuyến bay 0 điểm dừng
C31: Lọc 1 điểm dừng | D31: Kiểm tra lọc danh sách chuyến bay có "1 điểm dừng" | E31: Function | F31: Chỉ hiển thị chuyến bay quá cảnh 1 điểm
C32: Lọc 2+ điểm dừng | D32: Kiểm tra lọc danh sách chuyến bay có "2+ điểm dừng" | E32: Function | F32: Hiển thị chuyến bay từ 2 điểm quá cảnh trở lên
C33: Lọc 1 Hãng hàng không | D33: Kiểm tra lọc theo 1 Hãng hàng không cụ thể (VD: Vietnam Airlines) | E33: Function | F33: Chỉ hiển thị chuyến bay của 1 hãng chọn
C34: Lọc nhiều Hãng bay | D34: Kiểm tra lọc đồng thời nhiều Hãng hàng không | E34: Function | F34: Hiển thị chuyến bay thuộc các hãng đã tích
C35: Bỏ chọn lọc Hãng bay | D35: Kiểm tra bỏ tích chọn bộ lọc Hãng bay | E35: Function | F35: Khôi phục hiển thị đầy đủ các hãng
B36: 1.2.3 Lọc theo Khung giờ & Khoảng giá | C36: Lọc Giờ cất cánh | D36: Kiểm tra lọc theo Khung giờ cất cánh (Buổi sáng / Buổi trưa / Buổi chiều) | E36: Function | F36: Chỉ hiển thị chuyến bay khởi hành trong khung giờ
C37: Lọc Giờ hạ cánh | D37: Kiểm tra lọc theo Khung giờ hạ cánh | E37: Function | F37: Chỉ hiển thị chuyến bay hạ cánh trong khung giờ
C38: Lọc Khoảng giá vé | D38: Kiểm tra lọc theo thanh trượt Khoảng giá vé (Price Slider) | E38: Function | F38: Giá các chuyến bay <= giá đã kéo
C39: Lọc kết hợp đa tiêu chí | D39: Kiểm tra kết hợp đồng thời nhiều bộ lọc (Hãng bay + Khung giờ + Khoảng giá) | E39: Function | F39: Hiển thị chuyến bay thỏa mãn đồng thời tất cả tiêu chí
C40: Lọc không có kết quả | D40: Kiểm tra kết quả khi áp dụng bộ lọc không có chuyến bay phù hợp | E40: Validation | F40: Hiển thị màn hình trống kèm nút Đặt lại
...

Sheet Tìm kiếm chuyến bay
A2: Module Code | B2: Flight_Search | J2: Passed
A3: Test requirement | B3: Tìm kiếm chuyến bay | J3: Failed
A4: Tester | B4: Phan Thi Huynh Nhu | J4: Blocked
A5: Passed | B5: Failed | C5: Untested | D5: Blocked | E5: Skipped | F5: Number of Test cases | J5: Untested
A6: =COUNTIF(F9:F994,"Passed") -> 0 | B6: =COUNTIF(F9:F994,"Failed") -> 0 | C6: =F6-E6-D6-B6-A6 -> 25 | D6: =COUNTIF(F$9:F$994,"Blocked") -> 0 | E6: =COUNTIF(F$9:F$994,"Skipped") -> 0 | F6: =COUNTA(A9:A994) -> 25 | J6: Skipped
A8: ID | B8: Test Case Description | C8: Test Case Procedure | D8: Expected Output | E8: Inter-test case Dependence | F8: Result | G8: Test date | H8: Note
A9: Flight_Search_001 | B9: Kiểm tra hiển thị icon/menu "Vé máy bay" trên Trang chủ Traveloka | C9: Quan sát thanh menu điều hướng chính trên Trang chủ. | D9: Icon và menu "Vé máy bay" hiển thị rõ ràng, đúng vị trí và đúng thiết kế. | F9: Untested | G9: 46312
A10: Flight_Search_002 | B10: Kiểm tra click chọn "Vé máy bay" chuyển hướng sang giao diện Tìm kiếm | C10: 1. Click chọn menu "Vé máy bay". 2. Quan sát phản hồi của hệ thống. | D10: Hệ thống chuyển hướng thành công sang giao diện Tìm kiếm chuyến bay. Giao diện tải đầy đủ thông tin. | F10: Untested | G10: 46312
A11: Flight_Search_003 | B11: Kiểm tra bố cục giao diện chính của form Đặt vé máy bay | C11: Quan sát tổng thể màn hình Trang chủ Vé máy bay. | D11: Hiển thị đầy đủ: Form tìm kiếm (Điểm đi, Điểm đến, Ngày đi, Ngày về, Số hành khách, Hạng ghế) và nút [Tìm chuyến bay]. | F11: Untested | G11: 46312
A12: Flight_Search_004 | B12: Kiểm tra mặc định chọn loại vé "Một chiều" khi mới truy cập trang | C12: Quan sát trạng thái mặc định của loại chuyến bay. | D12: Hệ thống mặc định chọn loại vé "Một chiều". Ô chọn "Ngày về" bị ẩn hoặc làm mờ (disabled). | F12: Untested | G12: 46312
A13: Flight_Search_005 | B13: Kiểm tra chuyển đổi từ loại vé "Một chiều" sang "Khứ hồi" | C13: 1. Click chọn radio/tab "Khứ hồi". 2. Quan sát ô Ngày về. | D13: Trường "Ngày về" chuyển sang trạng thái kích hoạt (enabled) cho phép chọn ngày. | F13: Untested | G13: 46312
A14: Flight_Search_006 | B14: Kiểm tra chuyển đổi từ loại vé "Khứ hồi" về "Một chiều" | C14: 1. Click chọn lại radio/tab "Một chiều". 2. Quan sát ô Ngày về. | D14: Trường "Ngày về" bị ẩn/disabled, dữ liệu ngày về đã chọn trước đó bị xóa bỏ. | F14: Untested | G14: 46312
A15: Flight_Search_007 | B15: Kiểm tra hiển thị danh sách gợi ý khi nhập từ khóa thành phố/sân bay tiếng Việt có dấu | C15: 1. Nhập từ khóa (VD: "Hà Nội") vào ô Điểm đi. 2. Quan sát dropdown gợi ý. | D15: Hệ thống hiển thị danh sách các sân bay thuộc Hà Nội (VD: Sân bay Quốc tế Nội Bài - HAN). | F15: Untested | G15: 46312
A16: Flight_Search_008 | B16: Kiểm tra hiển thị danh sách gợi ý khi nhập từ khóa không dấu | C16: 1. Nhập từ khóa không dấu (VD: "Ho Chi Minh") vào ô Điểm đến. 2. Quan sát dropdown gợi ý. | D16: Hệ thống hiển thị đúng sân bay Tân Sơn Nhất - TP Hồ Chí Minh. | F16: Untested | G16: 46312
A17: Flight_Search_009 | B17: Kiểm tra gợi ý chuẩn xác khi nhập mã IATA của sân bay | C17: 1. Nhập mã IATA chuẩn (VD: "DAD") vào ô Điểm đến. 2. Quan sát danh sách gợi ý. | D17: Gợi ý hiển thị chính xác Sân bay Quốc tế Đà Nẵng - DAD. | F17: Untested | G17: 46312
A18: Flight_Search_010 | B18: Kiểm tra nhập từ khóa địa điểm không tồn tại | C18: 1. Nhập từ khóa vô nghĩa (VD: "@#$123") vào ô Điểm đi. 2. Quan sát dropdown. | D18: Hiển thị thông báo "Không tìm thấy kết quả phù hợp" trong dropdown gợi ý. | F18: Untested | G18: 46312
A19: Flight_Search_011 | B19: Kiểm tra nút xóa nhanh (icon [X]) tại ô Điểm đi / Điểm đến | C19: 1. Chọn Điểm đi là "Hà Nội (HAN)". 2. Click biểu tượng [X] tại ô nhập. | D19: Giá trị ô bị xóa sạch, quay trở lại trạng thái placeholder ban đầu. | F19: Untested | G19: 46312
A20: Flight_Search_012 | B20: Kiểm tra chức năng hoán đổi [⇆] vị trí giữa Điểm đi và Điểm đến | C20: 1. Chọn Điểm đi (HAN), Điểm đến (SGN). 2. Click vào nút hoán đổi [⇆]. | D20: Giá trị 2 ô tự động tráo đổi vị trí: Điểm đi thành SGN, Điểm đến thành HAN. | F20: Untested | G20: 46312
... A33: Flight_Search_025 | B33: Kiểm tra báo lỗi khi để trống trường bắt buộc (Điểm đi / Điểm đến / Ngày đi) | C33: 1. Để trống một trong các trường bắt buộc. 2. Click [Tìm chuyến bay]. | D33: Hệ thống không chuyển trang, hiển thị cảnh báo/báo lỗi đỏ tại các trường bị để trống. | F33: Untested | G33: 46312

Sheet Xem danh sách và chọn chuyến ba
A2: Module Code | B2: Flight_Select | J2: Passed
A3: Test requirement | B3: Xem danh sách và chọn chuyến bay | J3: Failed
A4: Tester | B4: Phan Thi Huynh Nhu | J4: Blocked
A5: Passed | B5: Failed | C5: Untested | D5: Blocked | E5: Skipped | F5: Number of Test cases | J5: Untested
A6: =COUNTIF(F9:F996,"Passed") -> 0 | B6: =COUNTIF(F9:F996,"Failed") -> 0 | C6: =F6-E6-D6-B6-A6 -> 25 | D6: =COUNTIF(F$9:F$996,"Blocked") -> 0 | E6: =COUNTIF(F$9:F$996,"Skipped") -> 0 | F6: =COUNTA(A9:A996) -> 25 | J6: Skipped
A8: ID | B8: Test Case Description | C8: Test Case Procedure | D8: Expected Output | E8: Inter-test case Dependence | F8: Result | G8: Test date | H8: Note
A9: Flight_Select_001 | B9: Kiểm tra hiển thị đầy đủ thông tin trên thẻ chuyến bay kết quả | C9: Quan sát các thẻ danh sách chuyến bay trả về. | D9: Hiển thị đầy đủ: Logo/Tên Hãng bay, Giờ cất/hạ cánh, Tổng thời gian bay, Loại chuyến bay, Giá vé. | F9: Untested | G9: 46312
A10: Flight_Select_002 | B10: Kiểm tra hiển thị số lượng tổng các chuyến bay tìm thấy | C10: Quan sát phần đầu trang danh sách kết quả. | D10: Hiển thị chính xác tổng số chuyến bay khớp với tiêu chí tìm kiếm (VD: "Tìm thấy 45 chuyến bay"). | F10: Untested | G10: 46312
A11: Flight_Select_003 | B11: Kiểm tra chuyển đổi ngày bay từ Thanh chọn ngày nhanh (Date Strip) | C11: 1. Click chọn một ngày khác trên thanh chọn ngày nhanh ở đầu trang. 2. Quan sát danh sách. | D11: Hệ thống tải lại và hiển thị danh sách chuyến bay của ngày mới được chọn. | F11: Untested | G11: 46312
A12: Flight_Select_004 | B12: Kiểm tra lọc danh sách chỉ hiển thị chuyến "Bay thẳng" | C12: 1. Tích chọn bộ lọc "Bay thẳng". 2. Quan sát kết quả. | D12: Danh sách tự động cập nhật chỉ còn lại các chuyến bay 0 điểm dừng. | F12: Untested | G12: 46312
A13: Flight_Select_005 | B13: Kiểm tra lọc danh sách chuyến bay có "1 điểm dừng" | C13: 1. Tích chọn bộ lọc "1 điểm dừng". 2. Quan sát kết quả. | D13: Danh sách tự động cập nhật chỉ hiển thị các chuyến bay quá cảnh 1 điểm dừng. | F13: Untested | G13: 46312
A14: Flight_Select_006 | B14: Kiểm tra lọc danh sách chuyến bay có "2+ điểm dừng" | C14: 1. Tích chọn bộ lọc "2+ điểm dừng". 2. Quan sát kết quả. | D14: Danh sách hiển thị các chuyến bay có từ 2 điểm quá cảnh trở lên. | F14: Untested | G14: 46312
A15: Flight_Select_007 | B15: Kiểm tra lọc theo 1 Hãng hàng không cụ thể (VD: Vietnam Airlines) | C15: 1. Tích chọn hãng "Vietnam Airlines". 2. Quan sát danh sách. | D15: Chỉ các chuyến bay thuộc Vietnam Airlines mới được hiển thị. | F15: Untested | G15: 46312
A16: Flight_Select_008 | B16: Kiểm tra lọc đồng thời nhiều Hãng hàng không | C16: 1. Tích chọn "Vietjet Air" và "Bamboo Airways". 2. Quan sát danh sách. | D16: Danh sách hiển thị kết quả bao gồm cả 2 hãng đã tích chọn. | F16: Untested | G16: 46312
A17: Flight_Select_009 | B17: Kiểm tra bỏ tích chọn bộ lọc Hãng bay | C17: 1. Bỏ tích chọn hãng đã lọc trước đó. 2. Quan sát danh sách. | D17: Danh sách khôi phục hiển thị đầy đủ các hãng hàng không. | F17: Untested | G17: 46312
A18: Flight_Select_010 | B18: Kiểm tra lọc theo Khung giờ cất cánh (Buổi sáng 00:00 - 06:00) | C18: 1. Tích chọn khung giờ 00:00 - 06:00. 2. Quan sát kết quả. | D18: Chỉ hiển thị các chuyến bay cất cánh trong khoảng từ 0h đến 6h sáng. | F18: Untested | G18: 46312
A19: Flight_Select_011 | B19: Kiểm tra lọc theo Khung giờ cất cánh (Buổi trưa/chiều 12:00 - 18:00) | C19: 1. Tích chọn khung giờ 12:00 - 18:00. 2. Quan sát kết quả. | D19: Chỉ hiển thị các chuyến bay khởi hành từ 12h đến 18h. | F19: Untested | G19: 46312
A20: Flight_Select_012 | B20: Kiểm tra lọc theo Khung giờ hạ cánh | C20: 1. Tích chọn khung giờ hạ cánh mong muốn. 2. Quan sát kết quả. | D20: Chỉ hiển thị các chuyến bay hạ cánh trong khung giờ đã chọn. | F20: Untested | G20: 46312
... A32: Flight_Select_024 | B32: Kiểm tra chọn chuyến bay Lượt đi và Lượt về đối với vé Khứ hồi | C32: 1. Click [Chọn] chuyến lượt đi. 2. Chọn tiếp chuyến lượt về. | D32: Hệ thống ghi nhận cả 2 chuyến và hiển thị thanh Tóm tắt 2 chuyến ở chân trang. | F32: Untested | G32: 46312
A33: Flight_Select_025 | B33: Kiểm tra click nút [Chọn / Select] chuyển sang trang Nhập thông tin | C33: Click nút [Chọn] chuyến bay ưng ý. | D33: Chuyển hướng thành công sang Màn hình Nhập thông tin đặt chỗ. | F33: Untested | G33: 17/10/2026

Sheet Đặt chỗ và thanh toán
A2: Module Code | B2: Flight_Payment | J2: Passed
A3: Test requirement | B3: Đặt chỗ và thanh toán | J3: Failed
A4: Tester | B4: Phan Thi Huynh Nhu | J4: Blocked
A5: Passed | B5: Failed | C5: Untested | D5: Blocked | E5: Skipped | F5: Number of Test cases | J5: Untested
A6: =COUNTIF(F9:F996,"Passed") -> 0 | B6: =COUNTIF(F9:F996,"Failed") -> 0 | C6: =F6-E6-D6-B6-A6 -> 25 | D6: =COUNTIF(F$9:F$996,"Blocked") -> 0 | E6: =COUNTIF(F$9:F$996,"Skipped") -> 0 | F6: =COUNTA(A9:A996) -> 25 | J6: Skipped
A8: ID | B8: Test Case Description | C8: Test Case Procedure | D8: Expected Output | E8: Inter-test case Dependence | F8: Result | G8: Test date | H8: Note
A9: Flight_Payment_001 | B9: Kiểm tra hiển thị giao diện Màn hình Nhập thông tin đặt chỗ | C9: Chuyển sang trang Đặt chỗ sau khi chọn vé. | D9: Hiển thị Form Thông tin người liên hệ, Form Hành khách, Dịch vụ bổ sung và Tóm tắt đơn hàng. | F9: Untested | G9: 46312
A10: Flight_Payment_002 | B10: Kiểm tra nhập đầy đủ và hợp lệ Thông tin người liên hệ và Hành khách | C10: Nhập đầy đủ Họ tên, SĐT, Email người liên hệ và Họ tên/Ngày sinh hành khách. | D10: Thông tin được ghi nhận hợp lệ, không báo lỗi. | F10: Untested | G10: 46312
A11: Flight_Payment_003 | B11: Kiểm tra báo lỗi khi để trống các trường thông tin bắt buộc | C11: 1. Để trống Họ tên, Email hoặc SĐT. 2. Click [Tiếp tục]. | D11: Hệ thống hiển thị thông báo lỗi đỏ tại các ô bị trống, không cho chuyển bước. | F11: Untested | G11: 46312
A12: Flight_Payment_004 | B12: Kiểm tra báo lỗi khi nhập Email sai định dạng (Thiếu @ hoặc tên miền) | C12: 1. Nhập email: "testemail.com". 2. Click [Tiếp tục]. | D12: Hệ thống báo lỗi "Email không hợp lệ". | F12: Untested | G12: 46312
A13: Flight_Payment_005 | B13: Kiểm tra báo lỗi khi nhập Số điện thoại chứa ký tự chữ/ký tự đặc biệt | C13: 1. Nhập SĐT: "090123abc#". 2. Click [Tiếp tục]. | D13: Hệ thống báo lỗi "Số điện thoại chỉ được chứa ký tự số". | F13: Untested | G13: 46312
A14: Flight_Payment_006 | B14: Kiểm tra báo lỗi khi nhập Số điện thoại không đủ/vượt quá độ dài tiêu chuẩn | C14: 1. Nhập SĐT quá ngắn (VD: "0901"). 2. Click [Tiếp tục]. | D14: Hệ thống báo lỗi "Số điện thoại không hợp lệ (phải từ 9-11 số)". | F14: Untested | G14: 46312
A15: Flight_Payment_007 | B15: Kiểm tra báo lỗi khi nhập Họ tên hành khách chứa chữ số hoặc ký tự đặc biệt | C15: 1. Nhập Họ tên: "Nguyen Van A123". 2. Click [Tiếp tục]. | D15: Hệ thống báo lỗi "Họ tên không hợp lệ". | F15: Untested | G15: 46312
A16: Flight_Payment_008 | B16: Kiểm tra tự động điền thông tin người dùng đã đăng nhập vào form | C16: Truy cập màn hình đặt chỗ khi đã đăng nhập tài khoản Traveloka. | D16: Thông tin Họ tên, Email, SĐT tự động fill sẵn vào các trường liên hệ. | F16: Untested | G16: 46312
A17: Flight_Payment_009 | B17: Kiểm tra chọn mua thêm gói Hành lý ký gửi (Extra Baggage) | C17: 1. Chọn mua gói hành lý 20kg. 2. Quan sát đơn hàng. | D17: Dịch vụ hành lý được thêm vào Tóm tắt đơn hàng, Tổng tiền tự động cộng thêm chi phí tương ứng. | F17: Untested | G17: 46312
A18: Flight_Payment_010 | B18: Kiểm tra chọn mua Suất ăn hoặc Bảo hiểm chuyến bay | C18: Tích chọn mua Suất ăn trên máy bay / Gói bảo hiểm. | D18: Chi phí dịch vụ được ghi nhận chính xác vào tổng giá tiền đơn hàng. | F18: Untested | G18: 46312
A19: Flight_Payment_011 | B19: Kiểm tra áp dụng Mã giảm giá / Voucher hợp lệ | C19: 1. Nhập mã voucher hợp lệ. 2. Click [Áp dụng]. | D19: Hệ thống báo áp dụng thành công, số tiền giảm giá được trừ trực tiếp vào Tổng thanh toán. | F19: Untested | G19: 46312
A20: Flight_Payment_012 | B20: Kiểm tra áp dụng Mã giảm giá hết hạn, sai mã hoặc không đủ điều kiện | C20: 1. Nhập mã voucher sai hoặc hết hạn. 2. Click [Áp dụng]. | D20: Hệ thống hiển thị lỗi "Mã giảm giá không tồn tại hoặc đã hết hạn". | F20: Untested | G20: 46312
... A33: Flight_Payment_025 | B33: Kiểm tra vô hiệu hóa nút [Thanh toán] tránh gửi trùng yêu cầu (Double Submission) | C33: 1. Chọn phương thức thanh toán hợp lệ. 2. Click nút [Thanh toán]. | D33: Nút [Thanh toán] tự động chuyển sang trạng thái disabled/loading ngay sau khi click. | F33: Untested | G33: 46312

Sheet Test Report
B1: TEST REPORT
B3: Project Name | C3: =Cover!C4 -> Traveloka - Tìm kiếm chuyến bay | E3: Creator | G3: Phan Thị Huỳnh Như
B4: Project Code | C4: =Cover!C5 -> TVL_FL_SEARCH | E4: Reviewer/Approver | G4: Trần Thị B
B5: Document Code | C5: =C4&"_"&"Test Report"&"_"&"v0.1" -> TVL_FL_SEARCH_Test Report_v0.1 | E5: Issue Date | G5: 46312
B6: Notes | C6: Release 1 includes 3 chức năng của module Tìm kiếm chuyến bay: Tìm kiếm chuyến bay, Xem danh sách và chọn chuyến bay, Đặt chỗ và thanh toán
B10: No | C10: Module code | D10: Pass | E10: Fail | F10: Untested | G10: Blocked | H10: Skipped | I10: Number of test cases
B11: 1 | C11: ='Tìm kiếm chuyến bay'!B2 -> Flight_Search | D11: ='Tìm kiếm chuyến bay'!A6 -> 0 | E11: ='Tìm kiếm chuyến bay'!B6 -> 0 | F11: ='Tìm kiếm chuyến bay'!C6 -> 25 | G11: ='Tìm kiếm chuyến bay'!D6 -> 0 | H11: ='Tìm kiếm chuyến bay'!E6 -> 0 | I11: ='Tìm kiếm chuyến bay'!F6 -> 25
B12: 2 | C12: ='Xem danh sách và chọn chuyến ba'!B2 -> Flight_Select | D12: ='Xem danh sách và chọn chuyến ba'!A6 -> 0 | E12: ='Xem danh sách và chọn chuyến ba'!B6 -> 0 | F12: ='Xem danh sách và chọn chuyến ba'!C6 -> 25 | G12: ='Xem danh sách và chọn chuyến ba'!D6 -> 0 | H12: ='Xem danh sách và chọn chuyến ba'!E6 -> 0 | I12: ='Xem danh sách và chọn chuyến ba'!F6 -> 25
B13: 3 | C13: ='Đặt chỗ và thanh toán'!B2 -> Flight_Payment | D13: ='Đặt chỗ và thanh toán'!A6 -> 0 | E13: ='Đặt chỗ và thanh toán'!B6 -> 0 | F13: ='Đặt chỗ và thanh toán'!C6 -> 25 | G13: ='Đặt chỗ và thanh toán'!D6 -> 0 | H13: ='Đặt chỗ và thanh toán'!E6 -> 0 | I13: ='Đặt chỗ và thanh toán'!F6 -> 25
C15: Sub total | D15: =SUM(D11:D13) -> 0 | E15: =SUM(E11:E13) -> 0 | F15: =SUM(F11:F13) -> 75 | G15: =SUM(G11:G13) -> 0 | H15: =SUM(H11:H13) -> 0 | I15: =SUM(I11:I13) -> 75
C17: Test coverage | E17: =(D15+E15)*100/(I15-H15-G15) -> 0 | F17: %
C18: Test successful coverage | E18: =D15*100/(D15+E15) -> #DIV/0! | F18: %
